Workbook

Sheet Products
A1: Worksheet-1 | B1: Products
B3: ProductID | C3: Product | D3: Price
B4: 101 | C4: Product A | D4: 120
B5: 102 | C5: Product B | D5: 150
B6: 103 | C6: Product C | D6: 200
B7: 104 | C7: Product D | D7: 90
B8: 105 | C8: Product E | D8: 220
B9: 106 | C9: Product F | D9: 130
B10: 107 | C10: Product G | D10: 250
B11: 108 | C11: Product H | D11: 300
H13: 6. Use VLOOKUP to find out which products from the Products worksheet have not been ordered.
H14: ProductID | I14: Product | J14: Price | K14: Ordered or Not
H15: 101 | I15: Product A | J15: 120 | K15: =IF(ISNA(VLOOKUP(H15,Orders!$C$3:$E$10,1,0)),"Not Ordered","Ordered") -> Ordered
H16: 102 | I16: Product B | J16: 150 | K16: =IF(ISNA(VLOOKUP(H16,Orders!$C$3:$E$10,1,0)),"Not Ordered","Ordered") -> Ordered
H17: 103 | I17: Product C | J17: 200 | K17: =IF(ISNA(VLOOKUP(H17,Orders!$C$3:$E$10,1,0)),"Not Ordered","Ordered") -> Ordered
H18: 104 | I18: Product D | J18: 90 | K18: =IF(ISNA(VLOOKUP(H18,Orders!$C$3:$E$10,1,0)),"Not Ordered","Ordered") -> Ordered
H19: 105 | I19: Product E | J19: 220 | K19: =IF(ISNA(VLOOKUP(H19,Orders!$C$3:$E$10,1,0)),"Not Ordered","Ordered") -> Ordered
H20: 106 | I20: Product F | J20: 130 | K20: =IF(ISNA(VLOOKUP(H20,Orders!$C$3:$E$10,1,0)),"Not Ordered","Ordered") -> Ordered
H21: 107 | I21: Product G | J21: 250 | K21: =IF(ISNA(VLOOKUP(H21,Orders!$C$3:$E$10,1,0)),"Not Ordered","Ordered") -> Ordered
H22: 108 | I22: Product H | J22: 300 | K22: =IF(ISNA(VLOOKUP(H22,Orders!$C$3:$E$10,1,0)),"Not Ordered","Ordered") -> Not Ordered

Sheet Orders
A1: Worksheet-2 | B1: Orders
B3: OrderId | C3: ProductId | D3: Quantity | E3: Total Price | H3: 1. Use VLOOKUP to find the product names for each ProductID in the Orders worksheet.
B4: 1 | C4: 101 | D4: 2
B5: 2 | C5: 103 | D5: 1 | H5: OrderId | I5: ProductId | J5: Quantity | K5: Product Names
B6: 3 | C6: 105 | D6: 4 | H6: 1 | I6: 101 | J6: 2 | K6: =VLOOKUP(I6,Products!$B$3:$D$9,2,0) -> Product A
B7: 4 | C7: 106 | D7: 3 | H7: 2 | I7: 103 | J7: 1 | K7: =VLOOKUP(I7,Products!$B$3:$D$9,2,0) -> Product C
B8: 5 | C8: 102 | D8: 5 | H8: 3 | I8: 105 | J8: 4 | K8: =VLOOKUP(I8,Products!$B$3:$D$9,2,0) -> Product E
B9: 6 | C9: 104 | D9: 6 | H9: 4 | I9: 106 | J9: 3 | K9: =VLOOKUP(I9,Products!$B$3:$D$9,2,0) -> Product F
B10: 7 | C10: 107 | D10: 7 | H10: 5 | I10: 102 | J10: 5 | K10: =VLOOKUP(I10,Products!$B$3:$D$9,2,0) -> Product B
H11: 6 | I11: 104 | J11: 6 | K11: =VLOOKUP(I11,Products!$B$3:$D$9,2,0) -> Product D
H15: 2. Use VLOOKUP to find the price for each ProductID in the Orders worksheet, then calculate the TotalPrice by multiplying the Quantity by the Product Price.
H16: OrderId | I16: ProductId | J16: Quantity | K16: Price | L16: Total Price
H17: 1 | I17: 101 | J17: 2 | K17: =VLOOKUP(I17,Products!$B$3:$D$9,3,0) -> 120 | L17: =J17*K17 -> 240
H18: 2 | I18: 103 | J18: 1 | K18: =VLOOKUP(I18,Products!$B$3:$D$9,3,0) -> 200 | L18: =J18*K18 -> 200
H19: 3 | I19: 105 | J19: 4 | K19: =VLOOKUP(I19,Products!$B$3:$D$9,3,0) -> 220 | L19: =J19*K19 -> 880
H20: 4 | I20: 106 | J20: 3 | K20: =VLOOKUP(I20,Products!$B$3:$D$9,3,0) -> 130 | L20: =J20*K20 -> 390
H21: 5 | I21: 102 | J21: 5 | K21: =VLOOKUP(I21,Products!$B$3:$D$9,3,0) -> 150 | L21: =J21*K21 -> 750
H22: 6 | I22: 104 | J22: 6 | K22: =VLOOKUP(I22,Products!$B$3:$D$9,3,0) -> 90 | L22: =J22*K22 -> 540
H26: 3. Use VLOOKUP to check if there are any ProductIDs in the Orders worksheet that do not exist in the Products worksheet.
H27: OrderId | I27: ProductId | J27: Quantity | K27: ProductID is available Products worksheet
H28: 1 | I28: 101 | J28: 2 | K28: =IF(ISNA(VLOOKUP(I28,Products!$B$3:$D$9,1,0)),"Not Exist", "Exist") -> Exist
H29: 2 | I29: 103 | J29: 1 | K29: =IF(ISNA(VLOOKUP(I29,Products!$B$3:$D$9,1,0)),"Not Exist", "Exist") -> Exist
H30: 3 | I30: 105 | J30: 4 | K30: =IF(ISNA(VLOOKUP(I30,Products!$B$3:$D$9,1,0)),"Not Exist", "Exist") -> Exist
H31: 4 | I31: 106 | J31: 3 | K31: =IF(ISNA(VLOOKUP(I31,Products!$B$3:$D$9,1,0)),"Not Exist", "Exist") -> Exist
H32: 5 | I32: 102 | J32: 5 | K32: =IF(ISNA(VLOOKUP(I32,Products!$B$3:$D$9,1,0)),"Not Exist", "Exist") -> Exist
H33: 6 | I33: 104 | J33: 6 | K33: =IF(ISNA(VLOOKUP(I33,Products!$B$3:$D$9,1,0)),"Not Exist", "Exist") -> Exist
H34: 7 | I34: 107 | J34: 7 | K34: =IF(ISNA(VLOOKUP(I34,Products!$B$3:$D$9,1,0)),"Not Exist", "Exist") -> Not Exist
H38: 4. Assume a discount of 10% is given on all products. Use VLOOKUP to find the original price and then calculate the discounted price.
H39: OrderId | I39: ProductId | J39: Quantity | K39: Discount Price | L39: Original Price
H40: 1 | I40: 101 | J40: 2 | K40: =VLOOKUP(I40,Products!$B$3:$D$9,3,0) -> 120 | L40: =K40+(K40*10%) -> 132
H41: 2 | I41: 103 | J41: 1 | K41: =VLOOKUP(I41,Products!$B$3:$D$9,3,0) -> 200 | L41: =K41+(K41*10%) -> 220
H42: 3 | I42: 105 | J42: 4 | K42: =VLOOKUP(I42,Products!$B$3:$D$9,3,0) -> 220 | L42: =K42+(K42*10%) -> 242
H43: 4 | I43: 106 | J43: 3 | K43: =VLOOKUP(I43,Products!$B$3:$D$9,3,0) -> 130 | L43: =K43+(K43*10%) -> 143
H44: 5 | I44: 102 | J44: 5 | K44: =VLOOKUP(I44,Products!$B$3:$D$9,3,0) -> 150 | L44: =K44+(K44*10%) -> 165
H45: 6 | I45: 104 | J45: 6 | K45: =VLOOKUP(I45,Products!$B$3:$D$9,3,0) -> 90 | L45: =K45+(K45*10%) -> 99
H50: 5. Use VLOOKUP to find the price for each ProductID and then calculate the order value. Find the maximum order value from the list.
H51: OrderId | I51: ProductId | J51: Quantity | K51: Price | L51: Order Value
H52: 1 | I52: 101 | J52: 2 | K52: =VLOOKUP(I52,Products!$B$3:$D$9,3,0) -> 120 | L52: =J52*K52 -> 240
H53: 2 | I53: 103 | J53: 1 | K53: =VLOOKUP(I53,Products!$B$3:$D$9,3,0) -> 200 | L53: =J53*K53 -> 200
H54: 3 | I54: 105 | J54: 4 | K54: =VLOOKUP(I54,Products!$B$3:$D$9,3,0) -> 220 | L54: =J54*K54 -> 880
...
